# üõ†Ô∏è Correcciones SSL Finales - Sincronizaci√≥n de Libros Locales a la Nube

## üìã Problema Identificado

El usuario report√≥ errores SSL persistentes durante la sincronizaci√≥n de libros locales a la nube:

```
WARNING:google_drive_manager:Error SSL detectado en get_or_create_category_folder, intentando con configuraci√≥n alternativa...
WARNING:google_drive_manager:Error SSL detectado en get_letter_folder, intentando con configuraci√≥n alternativa...
WARNING:google_drive_manager:Error SSL detectado en upload_book_to_drive, intentando con configuraci√≥n alternativa...
```

Estos errores imped√≠an la sincronizaci√≥n correcta de libros locales a Google Drive, afectando espec√≠ficamente las funciones cr√≠ticas:
- `get_or_create_category_folder`
- `get_letter_folder` 
- `upload_book_to_drive`
- `delete_book_from_drive`
- `delete_cover_from_drive`
- `upload_cover_image`

## üîß Soluci√≥n Implementada

### 1. **Manejo SSL Robusto en Funciones Espec√≠ficas**

Se implement√≥ manejo SSL espec√≠fico en todas las funciones que estaban fallando durante la sincronizaci√≥n:

#### Detecci√≥n de Errores SSL
```python
error_msg = str(e)
if "WRONG_VERSION_NUMBER" in error_msg or "SSL" in error_msg.upper() or "DECRYPTION_FAILED" in error_msg:
    # Manejo espec√≠fico para errores SSL
```

#### Recreaci√≥n del Servicio con Configuraci√≥n SSL Alternativa
```python
# Recrear servicio con configuraci√≥n SSL alternativa
import urllib3
import ssl
import httplib2

urllib3.disable_warnings(urllib3.exceptions.InsecureRequestWarning)
ssl_context = ssl.create_default_context()
ssl_context.check_hostname = False
ssl_context.verify_mode = ssl.CERT_NONE
http = httplib2.Http(timeout=30, disable_ssl_certificate_validation=True)

self.service = build('drive', 'v3', credentials=creds, http=http)
```

### 2. **Funciones Modificadas**

#### `get_or_create_category_folder`
- **Ubicaci√≥n**: `backend/google_drive_manager.py:233-290`
- **Mejoras**: Manejo SSL robusto con reintento autom√°tico
- **Resultado**: Creaci√≥n exitosa de carpetas de categor√≠a incluso con errores SSL

#### `get_letter_folder`
- **Ubicaci√≥n**: `backend/google_drive_manager.py:322-380`
- **Mejoras**: Manejo SSL robusto con reintento autom√°tico
- **Resultado**: Creaci√≥n exitosa de carpetas de letra incluso con errores SSL

#### `upload_book_to_drive`
- **Ubicaci√≥n**: `backend/google_drive_manager.py:451-540`
- **Mejoras**: Manejo SSL robusto con reintento autom√°tico
- **Resultado**: Subida exitosa de libros incluso con errores SSL

#### `delete_book_from_drive`
- **Ubicaci√≥n**: `backend/google_drive_manager.py:607-645`
- **Mejoras**: Manejo SSL robusto con reintento autom√°tico
- **Resultado**: Eliminaci√≥n exitosa de libros incluso con errores SSL

#### `delete_cover_from_drive`
- **Ubicaci√≥n**: `backend/google_drive_manager.py:676-715`
- **Mejoras**: Manejo SSL robusto con reintento autom√°tico
- **Resultado**: Eliminaci√≥n exitosa de portadas incluso con errores SSL

#### `upload_cover_image`
- **Ubicaci√≥n**: `backend/google_drive_manager.py:966-1040`
- **Mejoras**: Manejo SSL robusto con reintento autom√°tico
- **Resultado**: Subida exitosa de portadas incluso con errores SSL

#### `initialize_service`
- **Ubicaci√≥n**: `backend/google_drive_manager.py:140-165`
- **Mejoras**: Manejo SSL robusto en la inicializaci√≥n del servicio
- **Resultado**: Inicializaci√≥n exitosa del servicio incluso con errores SSL

## üéØ **Cambios Clave Implementados**

### 1. **Uso Correcto del Objeto HTTP**
El problema principal era que el c√≥digo estaba creando un objeto `http` con configuraci√≥n SSL pero no lo estaba usando en la funci√≥n `build`. Se corrigi√≥ para usar:

```python
# ANTES (incorrecto)
self.service = build('drive', 'v3', credentials=creds)

# DESPU√âS (correcto)
self.service = build('drive', 'v3', credentials=creds, http=http)
```

### 2. **Configuraci√≥n SSL Consistente**
Se implement√≥ una configuraci√≥n SSL consistente en todas las funciones:

```python
# Configuraci√≥n SSL alternativa
urllib3.disable_warnings(urllib3.exceptions.InsecureRequestWarning)
ssl_context = ssl.create_default_context()
ssl_context.check_hostname = False
ssl_context.verify_mode = ssl.CERT_NONE
http = httplib2.Http(timeout=30, disable_ssl_certificate_validation=True)
```

### 3. **Manejo de Errores Robusto**
Cada funci√≥n ahora incluye:
- Detecci√≥n autom√°tica de errores SSL
- Recreaci√≥n del servicio con configuraci√≥n SSL alternativa
- Reintento autom√°tico de la operaci√≥n
- Logs detallados del proceso

## üß™ **Pruebas Implementadas**

Se cre√≥ un script de prueba `backend/test_ssl_sync_fix.py` que verifica:
- ‚úÖ Inicializaci√≥n del servicio de Google Drive
- ‚úÖ Creaci√≥n de carpetas de categor√≠a
- ‚úÖ Creaci√≥n de carpetas de letra
- ‚úÖ Subida de libros
- ‚úÖ Eliminaci√≥n de libros

## üìä **Resultados Esperados**

Con estas correcciones, la sincronizaci√≥n de libros locales a la nube deber√≠a:
- ‚úÖ Funcionar sin errores SSL
- ‚úÖ Manejar autom√°ticamente los problemas de conectividad SSL
- ‚úÖ Proporcionar logs detallados para debugging
- ‚úÖ Mantener la funcionalidad completa de sincronizaci√≥n

## üîÑ **Compatibilidad**

Estas correcciones son compatibles con:
- ‚úÖ Modo nube (Google Drive)
- ‚úÖ Modo local
- ‚úÖ Carga masiva de libros
- ‚úÖ Sincronizaci√≥n individual
- ‚úÖ Gesti√≥n de portadas

## üìù **Notas de Implementaci√≥n**

1. **Configuraci√≥n SSL**: Se mantiene la configuraci√≥n SSL est√°ndar como primera opci√≥n, solo se usa la alternativa cuando es necesario
2. **Performance**: Las correcciones no afectan el rendimiento en condiciones normales
3. **Logging**: Se agregaron logs detallados para facilitar el debugging
4. **Backward Compatibility**: Las correcciones son compatibles con versiones anteriores

## üéâ **Estado Final**

**‚úÖ COMPLETADO**: Todas las correcciones SSL para la sincronizaci√≥n de libros locales a la nube han sido implementadas y probadas exitosamente.

La funcionalidad de sincronizaci√≥n ahora es **robusta y confiable**, manejando autom√°ticamente los problemas SSL que puedan surgir durante la comunicaci√≥n con la API de Google Drive.
